<?xml version="1.0"?>
<robot xmlns:xacro="http://www.ros.org/wiki/xacro" name="jimmy">
    <link name="base">
        <visual>
            <origin xyz="0 0 0" rpy="0 0 0" />
            <geometry>
                <box size =".94 .78 .198" />
                <!-- box size =".55 .78 .198" -->
            </geometry>
        </visual>
        
        <collision>
            <origin xyz="0 0 0" rpy="0 0 0" />
            <geometry>
                <box size =".94 .78 .198"/>
            </geometry>
        </collision>
    </link>

    <xacro:include filename="$(find gazebo_plugins)/test/multi_robot_scenario//xacro/laser/hokuyo.xacro" />
    <xacro:include filename="$(find velodyne_description)/urdf/VLP-16.urdf.xacro"/>
    <xacro:laser name="laser_vert_bottom" parent="base" xyz="0.3157894464801903 -0.002068548615034871 0.5099999434059285" rpy="3.1354753 -1.3045001 0.0024658" meshes="package://gazebo_plugins/test/multi_robot_scenario/meshes/laser" />
    <xacro:laser name="laser_vert_top_right" parent="base" xyz=".2978 -.1450 1.8451" rpy="-1.1760 .6313 -1.9377" meshes="package://gazebo_plugins/test/multi_robot_scenario/meshes/laser" />
    <xacro:laser name="laser_vert_top_left" parent="base" xyz=".2997 .1531 1.8443" rpy="1.1780 .6198 1.9560" meshes="package://gazebo_plugins/test/multi_robot_scenario/meshes/laser" />

    <VLP-16 parent="base" name="laser_horiz" topic="laser_horiz/packets" hz="10" samples="440" gpu="false">
        <origin xyz="0.2325416305773505 -0.0001380069427607134 1.920122926231907" rpy="-0.0012068 0.114646 -0.0015308" />
    </VLP-16>

    <xacro:macro name="wheel_xacro" params="suffix reflect">
        <link name="wheel_${suffix}">
            <visual>
                <origin xyz="-.1 ${reflect * .4} 0.0" rpy="-1.57079 0 0" />
                <geometry>
                    <cylinder radius=".2" length=".05"/>
                </geometry>
            </visual>
            
            <collision>
                <origin xyz="-.1 ${reflect * .4} 0.0" rpy="-1.57079 0 0" />
                <geometry>
                    <cylinder radius=".2" length=".05"/>
                </geometry>
            </collision>
        </link>

        <joint name="base_wheel_${suffix}_joint" type="continuous">
            <parent link="base"/>
            <child link="wheel_${suffix}"/>
            <origin xyz="-.1 .4 0.0" rpy="-1.57079 0 0" />
        </joint> 
    </xacro:macro>

    <xacro:wheel_xacro suffix="left" reflect="1" />
    <xacro:wheel_xacro suffix="right" reflect="-1" />

    <link name="wheel_center">
            <visual>
                <origin xyz=".1 0 0" rpy="-1.57079 0 0" />
                <geometry>
                    <cylinder radius=".15" length=".05"/>
                </geometry>
            </visual>
            
            <collision>
                <origin xyz=".1 0 0" rpy="-1.57079 0 0" />
                <geometry>
                    <cylinder radius=".15" length=".05"/>
                </geometry>
            </collision>
    </link>
    <joint name="base_wheel_center_joint" type="continuous">
            <parent link="base"/>
            <child link="wheel_center"/>
            <origin xyz=".1 0.0 0.0" rpy="-1.57079 0 0" />
    </joint>
</robot>
