<?xml version="1.0" ?>
<!-- =================================================================================== -->
<!-- |    This document was autogenerated by xacro from robot.xacro                    | -->
<!-- |    EDITING THIS FILE BY HAND IS NOT RECOMMENDED                                 | -->
<!-- =================================================================================== -->
<robot name="jimmy" xmlns:xacro="http://www.ros.org/wiki/xacro">
  <link name="base">
    <visual>
      <origin rpy="0 0 0" xyz="0 0 0"/>
      <geometry>
        <box size=".94 .78 .198"/>
        <!-- box size =".55 .78 .198" -->
      </geometry>
    </visual>
    <collision>
      <origin rpy="0 0 0" xyz="0 0 0"/>
      <geometry>
        <box size=".94 .78 .198"/>
      </geometry>
    </collision>
  </link>
  <link name="laser_vert_bottom">
    <visual>
      <origin rpy="3.1355 -1.3045 .0025" xyz=".3158 -.0021 .5100"/>
      <geometry>
        <box size=".062 .062 .087"/>
      </geometry>
    </visual>
    <collision>
      <origin rpy="3.1355 -1.3045 .0025" xyz=".3158 -.0021 .5100"/>
      <geometry>
        <box size=".062 .062 .087"/>
      </geometry>
    </collision>
  </link>
  <link name="laser_vert_top_right">
    <visual>
      <origin rpy="-1.1760 .6313 -1.9377" xyz=".2978 -.1450 1.8451"/>
      <geometry>
        <box size=".062 .062 .087"/>
      </geometry>
    </visual>
    <collision>
      <origin rpy="-1.1760 .6313 -1.9377" xyz=".2978 -.1450 1.8451"/>
      <geometry>
        <box size=".062 .062 .087"/>
      </geometry>
    </collision>
  </link>
  <link name="laser_vert_top_left">
    <visual>
      <origin rpy="1.1780 .6198 1.9560" xyz=".2997 .1531 1.8443"/>
      <geometry>
        <box size=".062 .062 .087"/>
      </geometry>
    </visual>
    <collision>
      <origin rpy="1.1780 .6198 1.9560" xyz=".2997 .1531 1.8443"/>
      <geometry>
        <box size=".062 .062 .087"/>
      </geometry>
    </collision>
  </link>
  <link name="laser_horiz">
    <visual>
      <origin rpy="-.0012068 .114646 -.0015308" xyz=".2325 .0001 1.9201"/>
      <geometry>
        <cylinder length=".072" radius=".052"/>
      </geometry>
    </visual>
    <collision>
      <origin rpy="-.0012068 .114646 -.0015308" xyz=".2325 .0001 1.9201"/>
      <geometry>
        <cylinder length=".072" radius=".052"/>
      </geometry>
    </collision>
  </link>
  <joint name="base_laser_vert_bottom_joint" type="fixed">
    <parent link="base"/>
    <child link="laser_vert_bottom"/>
    <origin rpy="3.1355 -1.3045 .0025" xyz=".3158 -.0021 .5100"/>
  </joint>
  <joint name="base_laser_vert_top_right_joint" type="fixed">
    <parent link="base"/>
    <child link="laser_vert_top_right"/>
    <origin rpy="-1.1760 .6313 -1.9377" xyz=".2978 -.1450 1.8451"/>
  </joint>
  <joint name="base_laser_vert_top_left_joint" type="fixed">
    <parent link="base"/>
    <child link="laser_vert_top_left"/>
    <origin rpy="1.1780 .6198 1.9560" xyz=".2997 .1531 1.8443"/>
  </joint>
  <joint name="base_laser_horiz_joint" type="fixed">
    <parent link="base"/>
    <child link="laser_horiz"/>
    <origin rpy=".2325 -.0001 1.9201" xyz=".2325 .0001 1.9201"/>
  </joint>
  <link name="wheel_left">
    <visual>
      <origin rpy="-1.57079 0 0" xyz="-.1 0.4 0.0"/>
      <geometry>
        <cylinder length=".05" radius=".2"/>
      </geometry>
    </visual>
    <collision>
      <origin rpy="-1.57079 0 0" xyz="-.1 0.4 0.0"/>
      <geometry>
        <cylinder length=".05" radius=".2"/>
      </geometry>
    </collision>
  </link>
  <joint name="base_wheel_left_joint" type="continuous">
    <parent link="base"/>
    <child link="wheel_left"/>
    <origin rpy="-1.57079 0 0" xyz="-.1 .4 0.0"/>
  </joint>
  <link name="wheel_right">
    <visual>
      <origin rpy="-1.57079 0 0" xyz="-.1 -0.4 0.0"/>
      <geometry>
        <cylinder length=".05" radius=".2"/>
      </geometry>
    </visual>
    <collision>
      <origin rpy="-1.57079 0 0" xyz="-.1 -0.4 0.0"/>
      <geometry>
        <cylinder length=".05" radius=".2"/>
      </geometry>
    </collision>
  </link>
  <joint name="base_wheel_right_joint" type="continuous">
    <parent link="base"/>
    <child link="wheel_right"/>
    <origin rpy="-1.57079 0 0" xyz="-.1 .4 0.0"/>
  </joint>
  <link name="wheel_center">
    <visual>
      <origin rpy="-1.57079 0 0" xyz=".1 0 0"/>
      <geometry>
        <cylinder length=".05" radius=".15"/>
      </geometry>
    </visual>
    <collision>
      <origin rpy="-1.57079 0 0" xyz=".1 0 0"/>
      <geometry>
        <cylinder length=".05" radius=".15"/>
      </geometry>
    </collision>
  </link>
  <joint name="base_wheel_center_joint" type="continuous">
    <parent link="base"/>
    <child link="wheel_center"/>
    <origin rpy="-1.57079 0 0" xyz=".1 0.0 0.0"/>
  </joint>
</robot>

